Workbook

Sheet Summary
A1: Aekobaba — live catalog export
A2: Exported 2026-10-12 14:24 UTC from the production database (read-only).
A4: Suppliers on the website | B4: =COUNTA(Suppliers!A:A)-1
A5: of which partners | B5: =COUNTIF(Suppliers!C:C,"Yes")
A6: Recommended | B6: =COUNTIF(Suppliers!D:D,"Recommended")
A7: Listed | B7: =COUNTIF(Suppliers!D:D,"Listed")
A8: Quote only | B8: =COUNTIF(Suppliers!D:D,"Quote only")
A9: Products on the website | B9: =COUNTA(Products!A:A)-1
A10: from partners | B10: =COUNTIF(Products!D:D,"Yes")
A11: with a published price | B11: =COUNT(Products!J:J)
A12: with a published MOQ | B12: =COUNT(Products!N:N)
A13: with a published lead time | B13: =COUNT(Products!P:P)
A14: Categories with listings | B14: =COUNTIF(Categories!D:D,">0")
A15: Categories (total) | B15: =COUNTA(Categories!A:A)-1
A16: Removed suppliers (hidden, still in database) | B16: =COUNTA('Removed Suppliers'!A:A)-1
A18: Notes
A19: Suppliers / Products / Categories / Price Breaks / Reviews / Certifications: only what the website shows (removed suppliers excluded).
A20: Partner rows are shaded. Prices are in the currency the supplier publishes (see Currency); 'Ask the supplier' = no published price.
A21: Not included: buyer inquiries, quote requests and user accounts — they hold personal contact details.

Sheet Suppliers
A1: Supplier | B1: Slug | C1: Partner | D1: Tier | E1: Location | F1: Website | G1: Listings on site | H1: Rating | I1: Rating count | J1: Rating platform | K1: Rating page | L1: Certifications | M1: Legal identity | N1: Last verified
A2: Berlin Packaging | B2: berlin-packaging | C2: Yes | D2: Listed | E2: US (Chicago, IL); 100+ locations worldwide | F2: https://www.berlinpackaging.com | G2: =COUNTIF(Products!$C:$C,A2) | H2: 4.4 | I2: 4779 | J2: Trustpilot | K2: https://www.trustpilot.com/review/berlinpackaging.com | N2: 2026-10-03
A3: Daehung Pack | B3: daehung-pack | C3: Yes | D3: Quote only | E3: China (Southern China) | F3: No website published | G3: =COUNTIF(Products!$C:$C,A3) | N3: 2026-10-10
A4: BottleStore.com (O.Berk Company) | B4: bottlestore-com | C4: No | D4: Recommended | E4: US | F4: https://www.bottlestore.com | G4: =COUNTIF(Products!$C:$C,A4) | H4: 4.4 | I4: 3503 | J4: Trustpilot | K4: https://www.trustpilot.com/review/bottlestore.com | M4: O.Berk Company (parent, founded 1910) | N4: 2026-09-21
A5: BoxUp | B5: boxup | C5: No | D5: Listed | E5: US | F5: https://www.boxup.com | G5: =COUNTIF(Products!$C:$C,A5) | N5: 2026-09-21
A6: Burch Bottle & Packaging, Inc. | B6: burch-bottle | C6: No | D6: Recommended | E6: US | F6: https://www.burchbottle.com | G6: =COUNTIF(Products!$C:$C,A6) | H6: 4.8 | I6: 2257 | J6: Trustpilot | K6: https://www.trustpilot.com/review/www.burchbottle.com | M6: Burch Bottle & Packaging, Inc. | N6: 2026-09-21
A7: Container & Packaging | B7: container-and-packaging | C7: No | D7: Quote only | E7: US (Boise, ID) | F7: https://www.containerandpackaging.com | G7: =COUNTIF(Products!$C:$C,A7) | H7: 4.8 | I7: 396 | J7: Trustpilot | K7: https://www.trustpilot.com/review/www.containerandpackaging.com | N7: 2026-10-06
A8: Custom Boxes Now | B8: custom-boxes-now | C8: No | D8: Listed | E8: US | F8: https://customboxesnow.com | G8: =COUNTIF(Products!$C:$C,A8) | H8: 4.8 | I8: 183 | J8: Trustpilot | K8: https://uk.trustpilot.com/review/customboxesnow.com | N8: 2026-09-21
A9: EcoEnclose | B9: ecoenclose | C9: No | D9: Recommended | E9: US | F9: https://www.ecoenclose.com | G9: =COUNTIF(Products!$C:$C,A9) | H9: 4.5 | I9: 61 | J9: Trustpilot | K9: https://www.trustpilot.com/review/ecoenclose.com | N9: 2026-09-21
A10: PackagingSupplies.com | B10: packagingsupplies-com | C10: No | D10: Listed | E10: US | F10: https://www.packagingsupplies.com | G10: =COUNTIF(Products!$C:$C,A10) | M10: Division of Cleveland Packaging, Inc. | N10: 2026-09-21
A11: Paper Mart | B11: paper-mart | C11: No | D11: Recommended | E11: US | F11: https://www.papermart.com | G11: =COUNTIF(Products!$C:$C,A11) | H11: 4.7 | I11: 9621 | J11: Trustpilot | K11: https://www.trustpilot.com/review/www.papermart.com | N11: 2026-09-21
A12: SKS Bottle & Packaging | B12: sks-bottle | C12: No | D12: Listed | E12: US | F12: https://www.sks-bottle.com | G12: =COUNTIF(Products!$C:$C,A12) | H12: 4.3 | I12: 3933 | J12: Trustpilot | K12: https://www.trustpilot.com/review/www.sks-bottle.com | N12: 2026-09-18
A13: Specialty Bottle | B13: specialty-bottle | C13: No | D13: Listed | E13: US | F13: https://www.specialtybottle.com | G13: =COUNTIF(Products!$C:$C,A13) | H13: 3.8 | I13: 9 | J13: Trustpilot | K13: https://www.trustpilot.com/review/specialtybottle.com | M13: Specialty Bottle Supply, LLC | N13: 2026-09-21
A14: Sticker Mule | B14: sticker-mule | C14: No | D14: Recommended | E14: US | F14: https://www.stickermule.com | G14: =COUNTIF(Products!$C:$C,A14) | H14: 4.7 | I14: 43782 | J14: Trustpilot | K14: https://www.trustpilot.com/review/stickermule.com | N14: 2026-09-21
A15: StickerApp | B15: stickerapp | C15: No | D15: Listed | E15: US / EU (Sweden) | F15: https://stickerapp.com | G15: =COUNTIF(Products!$C:$C,A15) | H15: 4.7 | I15: 20284 | J15: Trustpilot | K15: https://www.trustpilot.com/review/stickerapp.com | M15: StickerApp Inc. (US operations, Annapolis MD); Swedish parent (Lomma, Sweden) | N15: 2026-09-21
A16: The Packaging Lab | B16: the-packaging-lab | C16: No | D16: Quote only | E16: US (Brooklyn Park, MN) | F16: https://www.thepkglab.com | G16: =COUNTIF(Products!$C:$C,A16) | N16: 2026-10-06
A17: TricorBraun | B17: tricorbraun | C17: No | D17: Listed | E17: US | F17: https://www.tricorbraun.com | G17: =COUNTIF(Products!$C:$C,A17) | H17: 4.7 | I17: 41 | J17: Trustpilot | K17: https://www.trustpilot.com/review/tricorbraun.com | N17: 2026-09-18
A18: ePackageSupply | B18: epackage-supply | C18: No | D18: Recommended | E18: US | F18: https://epackagesupply.com | G18: =COUNTIF(Products!$C:$C,A18) | N18: 2026-09-21

Sheet Products
A1: Product | B1: Product ID | C1: Supplier | D1: Partner | E1: Supplier tier | F1: Category | G1: Subcategory | H1: Material | I1: Price type | J1: Price | K1: Currency | L1: Price basis | M1: Per-unit price (stated) | N1: MOQ | O1: MOQ unit | P1: Lead time (days) | Q1: Stock / custom | R1: Sample policy verified | S1: Product page (source) | T1: Image | U1: Captured | V1: Description
A2: 16 oz Clear PET Plastic General Purpose Jars (Caps Sold Separately) — 34317-B | B2: cmus06djh000tucu9sqh2k45q | C2: Berlin Packaging | D2: Yes | E2: Listed | F2: Plastic Jars & Canisters | G2: Wide-mouth jar | H2: Clear PET plastic | I2: Exact price | J2: 0.88 | K2: USD | L2: per jar (USD), cap sold separately | N2: Not published | P2: Not published | Q2: Stock | R2: No | S2: https://www.berlinpackaging.com/128-oz-clear-pet-plastic-wide-mouth-jars-cap-sold-separately-34398-b/ | T2: /products/plastic-jar.png | U2: 2026-10-02 | V2: Verbatim (2026-10-02): listed at "$0.88 Each" on the 128 oz Clear PET Plastic Wide Mouth Jars page. General purpose wide-mouth jar; caps sold separately.
A3: 16 oz Clear PET Plastic Spice Jars (Black Cap) — 2310B07BLK | B3: cmus06a2y000hucu9ydsxg30o | C3: Berlin Packaging | D3: Yes | E3: Listed | F3: Plastic Jars & Canisters | G3: Spice jar | H3: Clear PET plastic, PP cap | I3: Exact price | J3: 2.43 | K3: USD | L3: per jar with cap (USD) | N3: Not published | P3: Not published | Q3: Stock | R3: No | S3: https://www.berlinpackaging.com/2310b07wht-16-oz-clear-pet-plastic-spice-jars-white-cap/ | T3: /products/plastic-jar.png | U3: 2026-10-02 | V3: Verbatim (2026-10-02): listed at "$2.43 Each" on the 16 oz Clear PET Plastic Spice Jars page (2310B07WHT). Cap included; PP spice cap.
A4: 17 oz Clear PET Plastic Honey Bear Bottles (Cap Not Included) — 324050 | B4: cmus49wrd0006awu9kq4e9phw | C4: Berlin Packaging | D4: Yes | E4: Listed | F4: Plastic Bottles | G4: Honey bear bottle | H4: Clear PET plastic | I4: Exact price | J4: 0.79 | K4: USD | L4: per bottle (USD), cap sold separately | N4: Not published | P4: Not published | Q4: Stock | R4: No | S4: https://www.berlinpackaging.com/17-oz-clear-pet-plastic-honey-bear-bottles-cap-not-included-324050/ | T4: /partners/berlin-packaging/324050.webp | U4: 2026-10-03 | V4: Verbatim (2026-10-03): "Your VIP Price: $ 0.79" (each). 17 fl oz honey bear; caps sold separately.
A5: 3.5 oz 100% PCR Aluminum Packer Bottle — 38-400 Cap Size — 337048 | B5: cmus06fvx0011ucu9eyqix1w4 | C5: Berlin Packaging | D5: Yes | E5: Listed | F5: Metal Cans — Beverage & Food | G5: Aluminum packer bottle | H5: Aluminum (100% post-consumer recycled) | I5: Exact price | J5: 0.97 | K5: USD | L5: per bottle (USD), cap sold separately | N5: Not published | P5: Not published | Q5: Stock | R5: No | S5: https://www.berlinpackaging.com/3-5-oz-38-400-100-pct-pcr-aluminum-packer-bottle-337048/ | T5: /partners/berlin-packaging/337048.webp | U5: 2026-10-03 | V5: Verbatim (2026-10-03): "Your VIP Price: $ 0.97" (each). "100% PCR (post consumer recycled) aluminum"; "Cap size: 38-400 (sold separately)"; "Developed primarily for the nutraceutical and pharmaceutical industries"; ~1.77 in diameter x 3.74 in height.
A6: 4 oz Clear PET Plastic Spice Jar (Black Cap) — 322420-K | B6: cmus49z490009awu9uol85nve | C6: Berlin Packaging | D6: Yes | E6: Listed | F6: Plastic Jars & Canisters | G6: Spice jar | H6: Clear PET plastic, PP cap | I6: Exact price | J6: 0.74 | K6: USD | L6: per jar with cap (USD) | N6: Not published | P6: Not published | Q6: Stock | R6: No | S6: https://www.berlinpackaging.com/4-oz-clear-pet-plastic-spice-jar-black-cap-322420-k/ | T6: /partners/berlin-packaging/322420-K.webp | U6: 2026-10-03 | V6: Verbatim (2026-10-03): "Your VIP Price: $ 0.74" (each). "Includes a Black PP Plastic Cap". "Our clear PET jars have transparent convenience, with additional properties to preserve the robustness of dry spices, particularly those with high oil content."
A7: 4 oz Clear PET Plastic Spice Jar (Red Cap) — 322420-B | B7: cmus06cfe000pucu9d47farak | C7: Berlin Packaging | D7: Yes | E7: Listed | F7: Plastic Jars & Canisters | G7: Spice jar | H7: Clear PET plastic, PP cap with sifter | I7: Exact price | J7: 0.74 | K7: USD | L7: per jar with cap (USD) | N7: Not published | P7: Not published | Q7: Stock | R7: No | S7: https://www.berlinpackaging.com/4-oz-clear-pet-plastic-spice-jar-red-cap-322420-b/ | T7: /partners/berlin-packaging/322420-B.webp | U7: 2026-10-03 | V7: Verbatim (2026-10-03): "Your VIP Price: $ 0.74" (each). Includes a red PP plastic cap and a sifter fitment with 1/8" holes; "FDA Food Contact Compliant".
A8: 4 oz Clear PET Plastic Wide Mouth Packer Bottles (Cap Not Included) — 343936 | B8: cmus068uk000ducu9w19l1seu | C8: Berlin Packaging | D8: Yes | E8: Listed | F8: Plastic Bottles | G8: Packer bottle | H8: Clear PET plastic | I8: Exact price | J8: 0.42 | K8: USD | L8: per bottle (USD), cap sold separately | N8: Not published | P8: Not published | Q8: Stock | R8: No | S8: https://www.berlinpackaging.com/pet-plastic-wide-mouth-packer-bottles/ | T8: /products/plastic-bottle.png | U8: 2026-10-02 | V8: Verbatim (2026-10-02): listed at "$0.42 Each" on the PET Plastic Wide Mouth Packer Bottles page. Wide-mouth packer bottle for tablets, vitamins, powders; caps sold separately.
A9: 8 oz Clear PET Plastic Honey Bear Bottles (Cap Not Included) — 33512-B | B9: cmus49vp20004awu9r6ns9qw3 | C9: Berlin Packaging | D9: Yes | E9: Listed | F9: Plastic Bottles | G9: Honey bear bottle | H9: Clear PET plastic | I9: Exact price | J9: 0.65 | K9: USD | L9: per bottle (USD), cap sold separately | N9: Not published | P9: Not published | Q9: Stock | R9: No | S9: https://www.berlinpackaging.com/33512-b-8-oz-clear-pet-plastic-honey-bear-bottles-cap-not-included/ | T9: /partners/berlin-packaging/33512-B.webp | U9: 2026-10-03 | V9: Verbatim (2026-10-03): "Your VIP Price: $ 0.65" (each). "Cap Size: 38-400 (sold separately)"; lightweight, shatter-resistant PET; flat label panel front and back.
A10: 8 oz Clear PET Plastic Honey Bear Bottles (Cap Not Included) — 3351B09-B | B10: cmus0659o0001ucu9cd3qjnsx | C10: Berlin Packaging | D10: Yes | E10: Listed | F10: Plastic Bottles | G10: Honey bear bottle | H10: Clear PET plastic | I10: Exact price | J10: 0.6 | K10: USD | L10: per bottle (USD), cap sold separately | N10: Not published | P10: Not published | Q10: Stock | R10: No | S10: https://www.berlinpackaging.com/3351b09-b-8-oz-clear-pet-plastic-honey-bear-bottles-cap-not-included/ | T10: /partners/berlin-packaging/3351B09-B.webp | U10: 2026-10-03 | V10: Verbatim (2026-10-03): "Your VIP Price: $ 0.6" (each). "Cap Size: 38-400 (sold separately)"; "FDA Food Contact Compliant"; "BPA NI*"; front and back label panels; holds 8 fl oz (12 honey-weight oz). "Bulk pricing is not available for this item."
A11: 8 oz Clear PET Plastic Honey Bear Bottles (Flip-Top Cap) — 33512 | B11: cmus067n30009ucu9jnqyitgq | C11: Berlin Packaging | D11: Yes | E11: Listed | F11: Plastic Bottles | G11: Honey bear bottle | H11: Clear PET plastic, PP flip-top cap | I11: Exact price | J11: 1.61 | K11: USD | L11: per bottle with cap (USD) | N11: Not published | P11: Not published | Q11: Stock | R11: No | S11: https://www.berlinpackaging.com/33512-8-oz-clear-pet-plastic-honey-bear-bottles-flip-top-cap/ | T11: /partners/berlin-packaging/33512.webp | U11: 2026-10-03 | V11: Verbatim (2026-10-03): "Your VIP Price: $ 1.61" (each). Includes yellow PP low-profile flip-top cap with foam liner; flat label panel front and back; bulk pricing available on request.
A12: 8 oz Clear PET Plastic Honey Bear Bottles (Yellow Flip Top Cap) — 3351B09 | B12: cmus066gf0005ucu98bi4bcik | C12: Berlin Packaging | D12: Yes | E12: Listed | F12: Plastic Bottles | G12: Honey bear bottle | H12: Clear PET plastic, PP flip-top cap | I12: Exact price | J12: 1.38 | K12: USD | L12: per bottle with cap (USD) | N12: Not published | P12: Not published | Q12: Stock | R12: No | S12: https://www.berlinpackaging.com/3351b09-8-oz-clear-pet-plastic-honey-bear-bottles-yellow-flip-top-cap/ | T12: /partners/berlin-packaging/3351B09.webp | U12: 2026-10-03 | V12: Verbatim (2026-10-03): "Your VIP Price: $ 1.38" (each). Includes a yellow PP flip-top cap with foam liner; 8 fl oz (12 honey-weight oz); front/back label panels.
A13: 8 oz Clear PET Spice Jars (White Cap) — 2310B05WHT | B13: cmus06b6z000lucu9mqdxz2kt | C13: Berlin Packaging | D13: Yes | E13: Listed | F13: Plastic Jars & Canisters | G13: Spice jar | H13: Clear PET plastic, PP cap with sifter | I13: Exact price | J13: 1.97 | K13: USD | L13: per jar with cap (USD) | N13: Not published | P13: Not published | Q13: Stock | R13: No | S13: https://www.berlinpackaging.com/2310b05wht-8-4-oz-clear-pet-spice-jars-white-cap/ | T13: /partners/berlin-packaging/2310B05WHT.webp | U13: 2026-10-03 | V13: Verbatim (2026-10-03): "Your VIP Price: $ 1.97" (each). "8.4 oz. Clear PET Spice Jar"; "Sifter Fitment"; white PP spice cap included.
A14: 8 oz White HDPE Plastic Wide Mouth Jars (Cap Not Included) — 3301B08-B | B14: cmus06ena000xucu9vcg701x7 | C14: Berlin Packaging | D14: Yes | E14: Listed | F14: Plastic Jars & Canisters | G14: Wide-mouth jar | H14: White HDPE plastic | I14: Exact price | J14: 0.73 | K14: USD | L14: per jar (USD), cap sold separately | N14: Not published | P14: Not published | Q14: Stock | R14: No | S14: https://www.berlinpackaging.com/128-oz-clear-pet-plastic-wide-mouth-jars-cap-sold-separately-34398-b/ | T14: /products/plastic-jar.png | U14: 2026-10-02 | V14: Verbatim (2026-10-02): listed at "$0.73 Each" on the 128 oz Clear PET Plastic Wide Mouth Jars page. Caps not included.
A15: Brushed-Metal Effect Pouch | B15: cmv1z3bln0058acu9pckygjad | C15: Daehung Pack | D15: Yes | E15: Quote only | F15: Flexible Pouches & Bags | G15: Metallic pouch | H15: Printed flexible laminate | I15: Quote only | J15: Ask the supplier | N15: Not published | P15: Not published | Q15: Custom | R15: No | S15: /partners/daehung-pack/company-profile.pdf | T15: /partners/daehung-pack/metal-wire-drawing.jpg | U15: 2026-10-10 | V15: From Daehung Pack's company presentation (partner-supplied, 2026-10-10). Gold pouch with a brushed (wire-drawn) metal texture. No price, minimum or lead time stated for this format — quote on request.
A16: Coffee Bag with One-Way Valve | B16: cmv1z38mt0052acu9sztrsuuj | C16: Daehung Pack | D16: Yes | E16: Quote only | F16: Flexible Pouches & Bags | G16: Coffee pouch | H16: Printed flexible laminate | I16: Quote only | J16: Ask the supplier | N16: Not published | P16: Not published | Q16: Custom | R16: No | S16: /partners/daehung-pack/company-profile.pdf | T16: /partners/daehung-pack/coffee-bag-valve.jpg | U16: 2026-10-10 | V16: From Daehung Pack's company presentation (partner-supplied, 2026-10-10). White coffee bag with degassing valve. No price, minimum or lead time stated for this format — quote on request.
A17: Custom Printed Bag-in-Box | B17: cmv1z34ou004uacu9fe5emzja | C17: Daehung Pack | D17: Yes | E17: Quote only | F17: Flexible Pouches & Bags | G17: Bag-in-box | H17: Printed flexible laminate | I17: Quote only | J17: Ask the supplier | N17: 500 | O17: pieces (digital print; 10,000 pieces for gravure) | P17: Not published | Q17: Custom | R17: No | S17: /partners/daehung-pack/products-2025.pdf | T17: /partners/daehung-pack/bag-in-box.jpg | U17: 2026-10-10 | V17: From Daehung Pack's 2025 product catalog (partner-supplied, 2026-10-10). Ideal for bulk packing of liquids, oils and sauces. Print: digital or gravure. Colours: up to 10. Setup: none for digital; printing cylinders required for gravure. No price published — quote on request.
A18: Custom Printed Box Pouch (Flat Bottom) | B18: cmv1z2zqh004kacu91jw1tpuk | C18: Daehung Pack | D18: Yes | E18: Quote only | F18: Flexible Pouches & Bags | G18: Flat-bottom pouch | H18: Printed flexible laminate | I18: Quote only | J18: Ask the supplier | N18: 500 | O18: pieces (digital print; 10,000 pieces for gravure) | P18: Not published | Q18: Custom | R18: No | S18: /partners/daehung-pack/products-2025.pdf | T18: /partners/daehung-pack/box-pouch.jpg | U18: 2026-10-10 | V18: From Daehung Pack's 2025 product catalog (partner-supplied, 2026-10-10). Ideal for protein powder, pet food, grains and coffee beans. Print: digital or gravure. Colours: up to 10. Setup: none for digital; printing cylinders required for gravure. No price published — quote on request.
A19: Custom Printed Coffee Pouch | B19: cmv1z30q4004macu9utehqacy | C19: Daehung Pack | D19: Yes | E19: Quote only | F19: Flexible Pouches & Bags | G19: Coffee pouch | H19: Printed flexible laminate | I19: Quote only | J19: Ask the supplier | N19: 500 | O19: pieces (digital print; 10,000 pieces for gravure) | P19: Not published | Q19: Custom | R19: No | S19: /partners/daehung-pack/products-2025.pdf | T19: /partners/daehung-pack/coffee-pouch.jpg | U19: 2026-10-10 | V19: From Daehung Pack's 2025 product catalog (partner-supplied, 2026-10-10). Ideal for whole and ground beans, to preserve flavour and profile. Print: digital or gravure. Colours: up to 10. Setup: none for digital; printing cylinders required for gravure. No price published — quote on request.
A20: Custom Printed Form-Fill-Seal Film | B20: cmv1z37nd0050acu9ns7oyvmc | C20: Daehung Pack | D20: Yes | E20: Quote only | F20: Flexible Film Rollstock & Flow Wrap | G20: Form, fill and seal | H20: Printed flexible laminate | I20: Quote only | J20: Ask the supplier | N20: 1 | O20: roll (digital print; 5 rolls for gravure) | P20: Not published | Q20: Custom | R20: No | S20: /partners/daehung-pack/products-2025.pdf | T20: /partners/daehung-pack/form-fill-seal.jpg | U20: 2026-10-10 | V20: From Daehung Pack's 2025 product catalog (partner-supplied, 2026-10-10). Ideal for dry goods, lollies, salads, slices, bread, sausages and free-flow products. Print: digital or gravure. Colours: up to 10. Setup: none for digital; printing cylinders required for gravure. No price published — quote on request.
A21: Custom Printed Refill Pack | B21: cmv1z35og004wacu9blv2d59v | C21: Daehung Pack | D21: Yes | E21: Quote only | F21: Flexible Pouches & Bags | G21: Refill pack | H21: Printed flexible laminate | I21: Quote only | J21: Ask the supplier | N21: 500 | O21: pieces (digital print; 10,000 pieces for gravure) | P21: Not published | Q21: Custom | R21: No | S21: /partners/daehung-pack/products-2025.pdf | T21: /partners/daehung-pack/refill-pack.jpg | U21: 2026-10-10 | V21: From Daehung Pack's 2025 product catalog (partner-supplied, 2026-10-10). Ideal for bulk liquids, cosmetics, oils and cleaning supplies. Print: digital or gravure. Colours: up to 10. Setup: none for digital; printing cylinders required for gravure. No price published — quote on request.
A22: Custom Printed Roll Stock Film | B22: cmv1z36nx004yacu9o9sp7f0i | C22: Daehung Pack | D22: Yes | E22: Quote only | F22: Flexible Film Rollstock & Flow Wrap | H22: Printed flexible laminate | I22: Quote only | J22: Ask the supplier | N22: 1 | O22: roll (digital print; 5 rolls for gravure) | P22: Not published | Q22: Custom | R22: No | S22: /partners/daehung-pack/products-2025.pdf | T22: /partners/daehung-pack/rollstock.jpg | U22: 2026-10-10 | V22: From Daehung Pack's 2025 product catalog (partner-supplied, 2026-10-10). Ideal for various food products and applications. Print: digital or gravure. Colours: up to 10. Setup: none for digital; printing cylinders required for gravure. No price published — quote on request.
A23: Custom Printed Side Gusset Pouch | B23: cmv1z31q2004oacu9w0tkdqxj | C23: Daehung Pack | D23: Yes | E23: Quote only | F23: Flexible Pouches & Bags | G23: Side gusset pouch | H23: Printed flexible laminate | I23: Quote only | J23: Ask the supplier | N23: 500 | O23: pieces (digital print; 10,000 pieces for gravure) | P23: Not published | Q23: Custom | R23: No | S23: /partners/daehung-pack/products-2025.pdf | T23: /partners/daehung-pack/side-gusset-pouch.jpg | U23: 2026-10-10 | V23: From Daehung Pack's 2025 product catalog (partner-supplied, 2026-10-10). Ideal for coffee, pet food, legumes, powders, stock feeds and ingredient mixes. Print: digital or gravure. Colours: up to 10. Setup: none for digital; printing cylinders required for gravure. No price published — quote on request.
A24: Custom Printed Spout Pouch | B24: cmv1z32po004qacu90pgemx7g | C24: Daehung Pack | D24: Yes | E24: Quote only | F24: Flexible Pouches & Bags | G24: Spout pouch | H24: Printed flexible laminate | I24: Quote only | J24: Ask the supplier | N24: 500 | O24: pieces (digital print; 10,000 pieces for gravure) | P24: Not published | Q24: Custom | R24: No | S24: /partners/daehung-pack/products-2025.pdf | T24: /partners/daehung-pack/spout-pouch.jpg | U24: 2026-10-10 | V24: From Daehung Pack's 2025 product catalog (partner-supplied, 2026-10-10). Ideal for baby food, stocks, sauces, syrups, liquids and drinks. Print: digital or gravure. Colours: up to 10. Setup: none for digital; printing cylinders required for gravure. No price published — quote on request.
A25: Custom Printed Stand-Up Pouch | B25: cmv1z2yr0004iacu97l7ql9he | C25: Daehung Pack | D25: Yes | E25: Quote only | F25: Flexible Pouches & Bags | G25: Stand-up pouch | H25: Printed flexible laminate | I25: Quote only | J25: Ask the supplier | N25: 500 | O25: pieces (digital print; 10,000 pieces for gravure) | P25: Not published | Q25: Custom | R25: No | S25: /partners/daehung-pack/products-2025.pdf | T25: /partners/daehung-pack/stand-up-pouch.jpg | U25: 2026-10-10 | V25: From Daehung Pack's 2025 product catalog (partner-supplied, 2026-10-10). Ideal for dry goods, baking mixes, cereals, pasta, soups and liquids. Print: digital or gravure. Colours: up to 10. Setup: none for digital; printing cylinders required for gravure. No price published — quote on request.
A26: Custom Printed Vacuum Pouch | B26: cmv1z33pb004sacu9agfpsnuz | C26: Daehung Pack | D26: Yes | E26: Quote only | F26: Flexible Pouches & Bags | G26: Vacuum pouch | H26: Printed flexible laminate | I26: Quote only | J26: Ask the supplier | N26: 500 | O26: pieces (digital print; 10,000 pieces for gravure) | P26: Not published | Q26: Custom | R26: No | S26: /partners/daehung-pack/products-2025.pdf | T26: /partners/daehung-pack/vacuum-pouch.jpg | U26: 2026-10-10 | V26: From Daehung Pack's 2025 product catalog (partner-supplied, 2026-10-10). Ideal for salmon, cold meats, cheese and breads. Print: digital or gravure. Colours: up to 10. Setup: none for digital; printing cylinders required for gravure. No price published — quote on request.
A27: Matte Black Flat-Bottom Coffee Bag | B27: cmv1z3clp005aacu9b2cantqg | C27: Daehung Pack | D27: Yes | E27: Quote only | F27: Flexible Pouches & Bags | G27: Flat-bottom pouch | H27: Printed flexible laminate | I27: Quote only | J27: Ask the supplier | N27: Not published | P27: Not published | Q27: Custom | R27: No | S27: /partners/daehung-pack/company-profile.pdf | T27: /partners/daehung-pack/flat-bottom-coffee-bag.jpg | U27: 2026-10-10 | V27: From Daehung Pack's company presentation (partner-supplied, 2026-10-10). Matte black flat-bottom bag shown with Daehung Pack branding. No price, minimum or lead time stated for this format — quote on request.
A28: Specialty Paper Pouch | B28: cmv1z3als0056acu90l7vywxq | C28: Daehung Pack | D28: Yes | E28: Quote only | F28: Flexible Pouches & Bags | G28: Paper pouch | H28: Printed flexible laminate | I28: Quote only | J28: Ask the supplier | N28: Not published | P28: Not published | Q28: Custom | R28: No | S28: /partners/daehung-pack/company-profile.pdf | T28: /partners/daehung-pack/specialty-paper.jpg | U28: 2026-10-10 | V28: From Daehung Pack's company presentation (partner-supplied, 2026-10-10). Pouches in coloured specialty paper finishes. No price, minimum or lead time stated for this format — quote on request.
A29: Transparent High-Barrier Pouch | B29: cmv1z39m70054acu9l59373tz | C29: Daehung Pack | D29: Yes | E29: Quote only | F29: Flexible Pouches & Bags | G29: High-barrier pouch | H29: Printed flexible laminate | I29: Quote only | J29: Ask the supplier | N29: Not published | P29: Not published | Q29: Custom | R29: No | S29: /partners/daehung-pack/company-profile.pdf | T29: /partners/daehung-pack/high-barrier-clear.jpg | U29: 2026-10-10 | V29: From Daehung Pack's company presentation (partner-supplied, 2026-10-10). Clear high-barrier pouch with printed panel. No price, minimum or lead time stated for this format — quote on request.
A30: UV-Printed Roll Film | B30: cmv1z3dlp005cacu9u3dq7md9 | C30: Daehung Pack | D30: Yes | E30: Quote only | F30: Flexible Film Rollstock & Flow Wrap | H30: Printed flexible laminate | I30: Quote only | J30: Ask the supplier | N30: Not published | P30: Not published | Q30: Custom | R30: No | S30: /partners/daehung-pack/company-profile.pdf | T30: /partners/daehung-pack/uv-printed-film.jpg | U30: 2026-10-10 | V30: From Daehung Pack's company presentation (partner-supplied, 2026-10-10). Roll film with UV spot printing. No price, minimum or lead time stated for this format — quote on request.
A31: 16oz (480ml) Amber Boston Round Glass Bottle — 28-400 Neck | B31: cmuppwujc000y0wu9ots84qji | C31: BottleStore.com (O.Berk Company) | D31: No | E31: Recommended | F31: Glass Bottles | G31: Boston round | H31: Glass (amber soda-lime) | I31: Exact price | J31: 0.91 | K31: USD | L31: per piece (USD; carton of 12 at $10.92) | N31: 12 | O31: pieces (1 carton; carton pack 12) | P31: Not published | Q31: Stock | R31: No | S31: https://www.bottlestore.com/16oz-amber-boston-round-glass-bottle-12-pack-28-400-neck.html | T31: /products/glass-bottle-amber.png | U31: 2026-09-21 | V31: Verbatim (2026-09-21): "$ 0.91 (Per Piece) 12 Pieces per Carton; $10.92 (Per Carton); Buy 80 cartons for $10.18 each and save 7%; Buy 160 cartons for $9.36 each and save 14%; Buy 480 cartons for $9.31 each and save 15%" — volume tiers are per-carton prices (carton pack 12); per-piece tier figures are not published, so tiers stay out of the quantity-break table.
A32: 2oz (60ml) Flint (Clear) Big Bead Boston Round Glass Bottle — 20-400 Neck | B32: cmuppwvkm00100wu97nz10lze | C32: BottleStore.com (O.Berk Company) | D32: No | E32: Recommended | F32: Glass Bottles | G32: Boston round | H32: Glass (flint soda-lime) | I32: Exact price | J32: 0.2 | K32: USD | L32: per piece (USD; carton of 240; tiers quoted per carton) | N32: 240 | O32: pieces (1 carton; carton pack 240) | P32: Not published | Q32: Stock | R32: No | S32: https://www.bottlestore.com/2oz-flint-boston-round-glass-bottle-20-400-neck.html | T32: /products/glass-bottle.png | U32: 2026-09-21 | V32: Verbatim (2026-09-21): "Price Per $0.20; Buy 28 cartons for $44.90 each and save 6%; Buy 56 cartons for $41.28 each and save 14%; Buy 168 cartons for $39.37 each and save 18%" (per piece $0.20; carton pack 240). Base carton price not shown in the capture.
A33: 4oz (120ml) Amber Boston Round Glass Bottle — 22-405 Neck | B33: cmuppwwly00120wu96rnu8oal | C33: BottleStore.com (O.Berk Company) | D33: No | E33: Recommended | F33: Glass Bottles | G33: Boston round | H33: Glass (amber soda-lime) | I33: Exact price | J33: 59.2 | K33: USD | L33: per carton of 160 pieces (USD) | M33: 0.37 | N33: 160 | O33: pieces (1 carton; carton pack 160) | P33: Not published | Q33: Stock | R33: No | S33: https://www.bottlestore.com/4oz-120ml-amber-boston-round-glass-bottle-22-405.html | T33: /products/glass-bottle-amber.png | U33: 2026-09-21 | V33: Verbatim (2026-09-21): "$59.20 (Per Carton); Buy 18 cartons for $57.57 each and save 3%; Buy 36 cartons for $55.31 each and save 7%; Buy 108 cartons for $54.03 each and save 9%; Price Per $0.37" (carton pack 160; $0.37 per piece). "Pricing above is for container only. Discount does not apply to closure options."
A34: Custom Display Mailer Box (full-color CMYK, 9.5in x 7.75in x 4in) | B34: cmuppxm1q002u0wu9dwgh6rfq | C34: BoxUp | D34: No | E34: Listed | F34: Mailers & E-Commerce Shipping | H34: Not specified | I34: Exact price | J34: 4.58 | K34: USD | L34: per box at configurator default quantity of 252 (USD) | N34: 1 | O34: box ('No Minimums'; quantity-1 proofs available) | P34: Not published | Q34: Custom | R34: Yes | S34: https://www.boxup.com/product/display-mailer-box | T34: /products/mailer-kraft.png | U34: 2026-09-21 | V34: Verbatim (2026-09-21): "$4.58 / each" (per box). Configurator default quantity 252 (Subtotal $1,154.16); "No Minimums", quantity-1 proofs available.
A35: Custom Gift Mailer Box (top-tuck, 4in x 4in x 8in) | B35: cmuppxn35002w0wu9wpctnsch | C35: BoxUp | D35: No | E35: Listed | F35: Mailers & E-Commerce Shipping | H35: Not specified | I35: Exact price | J35: 1.91 | K35: USD | L35: per box at configurator default quantity (USD) | N35: 1 | O35: box ('No Minimums') | P35: Not published | Q35: Custom | R35: Yes | S35: https://www.boxup.com/product/top-open-gift-mailer-box | T35: /products/mailer-kraft.png | U35: 2026-09-21 | V35: Verbatim (2026-09-21): "$1.91 / each" (per box). Configurator default quantity (Subtotal $481.32); 5 sizes offered; "No Minimums". Captured from Exa's index of the first-party page.
A36: Stock Sample Display Mailer (pre-printed or blank) | B36: cmuppxo4h002y0wu9x4go2nxl | C36: BoxUp | D36: No | E36: Listed | F36: Mailers & E-Commerce Shipping | H36: Not specified | I36: Exact price | J36: 1 | K36: USD | L36: per sample box, plus shipping (USD) | N36: 1 | O36: sample box | P36: Not published | Q36: Stock | R36: Yes | S36: https://www.boxup.com/product/display-mailer-box-sample | T36: /products/mailer-kraft.png | U36: 2026-09-21 | V36: Verbatim (2026-09-21): "$1, plus shipping" (per sample box). "Order a stock pre-printed or plain blank sample Display Mailer box for only $1, plus shipping."
A37: 2oz Straight Sided Amber Glass Jars, 53-400 (Case of 24) — SKU 1SSA022GHG | B37: cmuppx73p00200wu9i357ygm2 | C37: Burch Bottle & Packaging, Inc. | D37: No | E37: Recommended | F37: Glass Jars | G37: Straight-sided jar | H37: Glass (amber soda-lime) | I37: Exact price | J37: 9.15 | K37: USD | L37: per case of 24 jars (USD) | N37: 24 | O37: jars (1 case) | P37: Not published | Q37: Stock | R37: No | S37: https://www.burchbottle.com/2oz-Amber-Straight-Sided-Jar-53-400 | T37: /products/glass-jar.png | U37: 2026-09-21 | V37: Verbatim (2026-09-21): "$9.15 / Case; Bulk Pricing: Buy 63 - 441 Cases and pay only $8.11 per Case; Buy 442 - 1767 Cases and pay only $7.30 per Case; Buy 1768 or more Cases and pay only $6.64 per Case" (per case of 24 jars; tiers are per-case prices, so they stay out of the quantity-break table). Pallet quantity 442 cases.
A38: 4oz Amber Straight Sided Jar — 58/400 Finish (Case of 24) | B38: cmuppx96s00240wu9wpp49cdt | C38: Burch Bottle & Packaging, Inc. | D38: No | E38: Recommended | F38: Glass Jars | G38: Straight-sided jar | H38: Glass (amber soda-lime) | I38: Exact price | J38: 13.33 | K38: USD | L38: per case of 24 jars (USD) | N38: 24 | O38: jars (1 case) | P38: Not published | Q38: Stock | R38: No | S38: https://www.burchbottle.com/2oz-Amber-Straight-Sided-Jar-53-400 | T38: /products/glass-jar.png | U38: 2026-09-21 | V38: Verbatim (2026-09-21): "$13.33 / Case" (per case of 24 jars); shown as a related product on the live 2 oz jar page.
A39: 8 oz Flint Boston Round Bottle — 28/400 Finish (Case of 12) — SKU 1BR080211SGC | B39: cmuppx85900220wu95534as4v | C39: Burch Bottle & Packaging, Inc. | D39: No | E39: Recommended | F39: Glass Bottles | G39: Boston round | H39: Glass (flint soda-lime) | I39: Exact price | J39: 9.4 | K39: USD | L39: per case of 12 bottles (USD) | N39: 12 | O39: bottles (1 case) | P39: Not published | Q39: Stock | R39: No | S39: https://www.burchbottle.com/8oz-Flint-Boston-Round-28-400-2 | T39: /products/glass-bottle.png | U39: 2026-09-21 | V39: Verbatim (2026-09-21): "$9.40 / Case; Buy 82 - 307 Cases and pay only $7.52 per Case; Buy 308 - 1231 Cases and pay only $6.79 per Case; Buy 1232 or more Cases and pay only $6.09 per Case" (per case of 12 bottles). Pallet quantity 154 cases.
A40: Deep Metal Tins (range) | B40: cmuwulyk80083l4u95nflofvf | C40: Container & Packaging | D40: No | E40: Quote only | F40: Metal Tins | H40: Metal (tinplate) | I40: Quote only | J40: Ask the supplier | N40: Not published | P40: Not published | Q40: Stock | R40: No | S40: https://www.containerandpackaging.com/catalog/metal-containers/deep-metal-tins/ | T40: /products/metal-tin.png | U40: 2026-10-06 | V40: Captured 2026-10-06: catalog range page; no prices published.
...

Sheet Categories
A1: Category | B1: Slug | C1: Parent | D1: Live listings | E1: Description
A2: Aerosol Cans | B2: aerosols | D2: =COUNTIF(Products!$F:$F,A2)
A3: Blister Packs, Clamshells & Thermoform Trays | B3: thermoforms | D3: =COUNTIF(Products!$F:$F,A3)
A4: Branding Accessories: Hang Tags, Stickers, Tissue & Tape | B4: brand-accessories | D4: =COUNTIF(Products!$F:$F,A4)
A5: Child-Resistant & Cannabis Specialty Packaging | B5: cr-cannabis | D5: =COUNTIF(Products!$F:$F,A5)
A6: Closures | B6: closures | D6: =COUNTIF(Products!$F:$F,A6)
A7: Collapsible Tubes | B7: collapsible-tubes | D7: =COUNTIF(Products!$F:$F,A7)
A8: Compostables & Sustainable Structures | B8: compostables | D8: =COUNTIF(Products!$F:$F,A8)
A9: Corrugated Shippers & Secondary Packaging | B9: corrugated | D9: =COUNTIF(Products!$F:$F,A9) | E9: Every CPG SKU ships in this category — corrugated cases, pallets, and stretch wrap are standard across food, beverage, and household distribution.
A10: Dropper Assemblies, Vials & Roll-Ons | B10: droppers-vials | D10: =COUNTIF(Products!$F:$F,A10)
A11: Flexible Film Rollstock & Flow Wrap | B11: rollstock | D11: =COUNTIF(Products!$F:$F,A11)
A12: Flexible Pouches & Bags | B12: pouches-bags | D12: =COUNTIF(Products!$F:$F,A12) | E12: The highest-frequency primary pack in food CPG (stand-up, flat-bottom, side-gusset, lay-flat formats); flexible formats account for over 38% of global food packaging volume per the taxonomy corpus.
A13: Folding Cartons | B13: folding-cartons | D13: =COUNTIF(Products!$F:$F,A13)
A14: Glass Bottles | B14: glass-bottles | D14: =COUNTIF(Products!$F:$F,A14) | E14: Stock glass starts at zero MOQ from US distributors and ~5,000–10,000 units from import programs; custom glass is tooling-driven.
A15: Glass Jars | B15: glass-jars | D15: =COUNTIF(Products!$F:$F,A15)
A16: Labels | B16: labels | D16: =COUNTIF(Products!$F:$F,A16)
A17: Mailers & E-Commerce Shipping | B17: mailers | D17: =COUNTIF(Products!$F:$F,A17)
A18: Metal Cans — Beverage & Food | B18: metal-cans | D18: =COUNTIF(Products!$F:$F,A18)
A19: Metal Tins | B19: metal-tins | D19: =COUNTIF(Products!$F:$F,A19)
A20: Plastic Bottles | B20: plastic-bottles | D20: =COUNTIF(Products!$F:$F,A20)
A21: Plastic Jars & Canisters | B21: plastic-jars | D21: =COUNTIF(Products!$F:$F,A21)
A22: Pumps, Sprayers & Airless Dispensers | B22: pumps-sprayers | D22: =COUNTIF(Products!$F:$F,A22)
A23: Rigid Setup Boxes | B23: setup-boxes | D23: =COUNTIF(Products!$F:$F,A23)
A24: Sachets & Stick Packs | B24: sachets-stick-packs | D24: =COUNTIF(Products!$F:$F,A24)
A25: Shrink Sleeves | B25: shrink-sleeves | D25: =COUNTIF(Products!$F:$F,A25)
A26: Tubs, Cups & Pails | B26: tubs-pails | D26: =COUNTIF(Products!$F:$F,A26)

Sheet Price Breaks
A1: Product | B1: Supplier | C1: Min qty | D1: Max qty | E1: Unit price | F1: Currency | G1: Price basis
A2: 4 oz Amber Boston Round Glass Bottle with Black Cap (BRA4) | B2: Specialty Bottle | C2: 1 | D2: 127 | E2: 0.65 | F2: USD | G2: per bottle (USD)
A3: 4 oz Amber Boston Round Glass Bottle with Black Cap (BRA4) | B3: Specialty Bottle | C3: 128 | D3: 999 | E3: 0.62 | F3: USD | G3: per bottle (USD)
A4: 4 oz Amber Boston Round Glass Bottle with Black Cap (BRA4) | B4: Specialty Bottle | C4: 1000 | D4: 4999 | E4: 0.56 | F4: USD | G4: per bottle (USD)
A5: 4 oz Amber Boston Round Glass Bottle with Black Cap (BRA4) | B5: Specialty Bottle | C5: 5000 | D5: 9999 | E5: 0.51 | F5: USD | G5: per bottle (USD)
A6: 4 oz Amber Boston Round Glass Bottle with Black Cap (BRA4) | B6: Specialty Bottle | C6: 10000 | D6: 25000 | E6: 0.44 | F6: USD | G6: per bottle (USD)
A7: 4 oz Amber Boston Round Glass Bottle with Silver Cap (BRA4S) | B7: Specialty Bottle | C7: 1 | D7: 127 | E7: 0.69 | F7: USD | G7: per bottle (USD)
A8: 4 oz Amber Boston Round Glass Bottle with Silver Cap (BRA4S) | B8: Specialty Bottle | C8: 128 | D8: 999 | E8: 0.64 | F8: USD | G8: per bottle (USD)
A9: 4 oz Amber Boston Round Glass Bottle with Silver Cap (BRA4S) | B9: Specialty Bottle | C9: 1000 | D9: 4999 | E9: 0.58 | F9: USD | G9: per bottle (USD)
A10: 4 oz Amber Boston Round Glass Bottle with Silver Cap (BRA4S) | B10: Specialty Bottle | C10: 5000 | D10: 9999 | E10: 0.52 | F10: USD | G10: per bottle (USD)
A11: 4 oz Amber Boston Round Glass Bottle with Silver Cap (BRA4S) | B11: Specialty Bottle | C11: 10000 | D11: 25000 | E11: 0.46 | F11: USD | G11: per bottle (USD)
A12: 8 oz Amber Boston Round Glass Bottle with Black Cap (BRA8) | B12: Specialty Bottle | C12: 1 | D12: 191 | E12: 1.7 | F12: USD | G12: per bottle (USD)
A13: 8 oz Amber Boston Round Glass Bottle with Black Cap (BRA8) | B13: Specialty Bottle | C13: 192 | D13: 999 | E13: 1.47 | F13: USD | G13: per bottle (USD)
... A15: 8 oz Amber Boston Round Glass Bottle with Black Cap (BRA8) | B15: Specialty Bottle | C15: 5000 | D15: 10000 | E15: 0.87 | F15: USD | G15: per bottle (USD)

Sheet Reviews
A1: Supplier | B1: Platform | C1: Score | D1: Reviewed | E1: Review page | F1: Captured | G1: Summary
A2: Berlin Packaging | B2: Trustpilot | C2: 4.4 | D2: 2026-10-03 | E2: https://www.trustpilot.com/review/berlinpackaging.com | F2: 2026-10-03
A3: BottleStore.com (O.Berk Company) | B3: Trustpilot | C3: 4.4 | D3: 2026-09-21 | E3: https://www.trustpilot.com/review/bottlestore.com | F3: 2026-09-21
A4: Burch Bottle & Packaging, Inc. | B4: Trustpilot | C4: 4.8 | D4: 2026-09-21 | E4: https://www.trustpilot.com/review/www.burchbottle.com | F4: 2026-09-21
A5: Container & Packaging | B5: Trustpilot | C5: 4.8 | D5: 2026-09-18 | E5: https://www.trustpilot.com/review/www.containerandpackaging.com | F5: 2026-09-18
A6: Custom Boxes Now | B6: Trustpilot | C6: 4.8 | D6: 2026-09-21 | E6: https://uk.trustpilot.com/review/customboxesnow.com | F6: 2026-09-21
A7: EcoEnclose | B7: Trustpilot | C7: 4.5 | D7: 2026-09-21 | E7: https://www.trustpilot.com/review/ecoenclose.com | F7: 2026-09-21
A8: Paper Mart | B8: Trustpilot | C8: 4.7 | D8: 2026-09-21 | E8: https://www.trustpilot.com/review/www.papermart.com | F8: 2026-09-21
A9: SKS Bottle & Packaging | B9: Trustpilot | C9: 4.3 | D9: 2026-09-18 | E9: https://www.trustpilot.com/review/www.sks-bottle.com | F9: 2026-09-18
A10: Specialty Bottle | B10: Trustpilot | C10: 3.8 | D10: 2026-09-21 | E10: https://www.trustpilot.com/review/specialtybottle.com | F10: 2026-09-21
A11: Sticker Mule | B11: Trustpilot | C11: 4.7 | D11: 2026-09-21 | E11: https://www.trustpilot.com/review/stickermule.com | F11: 2026-09-21
A12: StickerApp | B12: Trustpilot | C12: 4.7 | D12: 2026-09-21 | E12: https://www.trustpilot.com/review/stickerapp.com | F12: 2026-09-21
A13: TricorBraun | B13: Trustpilot | C13: 4.7 | D13: 2026-09-18 | E13: https://www.trustpilot.com/review/tricorbraun.com | F13: 2026-09-18

Sheet Certifications
A1: Supplier | B1: Certification | C1: Source | D1: Captured

Sheet Removed Suppliers
A1: Supplier | B1: Slug | C1: Location | D1: Website | E1: Listings (hidden)
A2: BOWE PACK | B2: bowe-pack | C2: China | D2: https://bowepack.com | E2: 0
A3: CXPACK (Shenzhen Chengxing Packing & Material) | B3: cxpack | C3: China | D3: https://www.cxpack.com | E3: 3
A4: Cambay Foodservice Packaging (Cambay Technopack Pvt. Ltd.) | B4: cambay-foodservice | C4: India | D4: https://www.cambay.co.in | E4: 0
A5: Cangzhou Yunfeng Packaging Products Co., Ltd. | B5: cangzhou-yunfeng | C5: China | D5: https://www.yunfengpackaging.com | E5: 3
A6: Carton Service | B6: carton-service | C6: EU (France) | D6: https://www.cartonservice.fr | E6: 3
A7: Davpack | B7: davpack | C7: UK | D7: https://www.davpack.co.uk | E7: 3
A8: DinoLabelDigital | B8: dinolabel-digital | C8: India | D8: https://dinolabeldigital.com | E8: 3
A9: Glory Tins Co., Ltd. | B9: glory-tins | C9: China | D9: https://glorytins.com | E9: 0
A10: Kite Packaging | B10: kite-packaging | C10: UK | D10: https://www.kitepackaging.co.uk | E10: 0
A11: Lil Packaging | B11: lil-packaging | C11: UK | D11: https://lilpackaging.com | E11: 2
A12: Macfarlane Packaging | B12: macfarlane-packaging | C12: UK | D12: https://www.macfarlanepackaging.com | E12: 0
A13: Maruthi Plastics | B13: maruthi-plastics | C13: India | D13: https://maruthiplastics.in | E13: 3
... A24: verpacking.com | B24: verpacking | C24: EU (Germany) | D24: https://www.verpacking.com | E24: 3
